/usr/local/bin/solver: line 18:    17 Segmentation fault      (core dumped) its-conversion --to smt2 $bench > $filename
[20] Failed to execute script irankfinder
Traceback (most recent call last):
  File "lark/parsers/lalr_parser.py", line 46, in get_action
KeyError: 'CNAME'

During handling of the above exception, another exception occurred:

Traceback (most recent call last):
  File "irankfinder.py", line 190, in parse_file
  File "genericparser/__init__.py", line 109, in parse
  File "genericparser/Parser_smt2.py", line 25, in parse
  File "genericparser/Parser_fc.py", line 25, in parse_string
  File "lark/lark.py", line 197, in parse
  File "lark/parser_frontends.py", line 37, in parse
  File "lark/parsers/lalr_parser.py", line 71, in parse
  File "lark/parsers/lalr_parser.py", line 50, in get_action
lark.common.UnexpectedToken: Unexpected token Token(CNAME, 'File') at line 1, column 0.
Expected: dict_keys(['__LBRACE', 'dict', 'start'])
Context: <no context>

The above exception was the direct cause of the following exception:

Traceback (most recent call last):
  File "irankfinder.py", line 374, in <module>
  File "irankfinder.py", line 205, in launch
  File "irankfinder.py", line 197, in parse_file
Exception
